Traceback (most recent call last):
  File "/Users/haochen/Codebase/tadv/tadv/runtime_environments/python/env/lib/python3.12/site-packages/pandas/core/indexes/base.py", line 3805, in get_loc
    return self._engine.get_loc(casted_key)
           ^^^^^^^^^^^^^^^^^^^^^^^^^^^^^^^^
  File "index.pyx", line 167, in pandas._libs.index.IndexEngine.get_loc
  File "index.pyx", line 196, in pandas._libs.index.IndexEngine.get_loc
  File "pandas/_libs/hashtable_class_helper.pxi", line 7081, in pandas._libs.hashtable.PyObjectHashTable.get_item
  File "pandas/_libs/hashtable_class_helper.pxi", line 7089, in pandas._libs.hashtable.PyObjectHashTable.get_item
KeyError: 'admission_date'

The above exception was the direct cause of the following exception:

Traceback (most recent call last):
  File "/Users/haochen/Codebase/tadv/data/healthcare_dataset/scripts/ml_inference/classification_6.py", line 64, in <module>
    test_df["admission_date"] = pd.to_datetime(test_df["admission_date"], errors="coerce").astype(np.int64) // 10 ** 9
                                               ~~~~~~~^^^^^^^^^^^^^^^^^^
  File "/Users/haochen/Codebase/tadv/tadv/runtime_environments/python/env/lib/python3.12/site-packages/pandas/core/frame.py", line 4102, in __getitem__
    indexer = self.columns.get_loc(key)
              ^^^^^^^^^^^^^^^^^^^^^^^^^
  File "/Users/haochen/Codebase/tadv/tadv/runtime_environments/python/env/lib/python3.12/site-packages/pandas/core/indexes/base.py", line 3812, in get_loc
    raise KeyError(key) from err
KeyError: 'admission_date'
