/Users/haochen/Codebase/cadv-exploration/cadv_exploration/runtime_environments/python/env/lib/python3.9/site-packages/pandas/core/arraylike.py:399: RuntimeWarning: invalid value encountered in log1p
  result = getattr(ufunc, method)(*inputs, **kwargs)
Traceback (most recent call last):
  File "/Users/haochen/Codebase/cadv-exploration/data/healthcare_dataset/scripts/ml/classification_3.py", line 40, in <module>
    X_test = test_df[feature_cols].copy()
  File "/Users/haochen/Codebase/cadv-exploration/cadv_exploration/runtime_environments/python/env/lib/python3.9/site-packages/pandas/core/frame.py", line 4108, in __getitem__
    indexer = self.columns._get_indexer_strict(key, "columns")[1]
  File "/Users/haochen/Codebase/cadv-exploration/cadv_exploration/runtime_environments/python/env/lib/python3.9/site-packages/pandas/core/indexes/base.py", line 6200, in _get_indexer_strict
    self._raise_if_missing(keyarr, indexer, axis_name)
  File "/Users/haochen/Codebase/cadv-exploration/cadv_exploration/runtime_environments/python/env/lib/python3.9/site-packages/pandas/core/indexes/base.py", line 6252, in _raise_if_missing
    raise KeyError(f"{not_found} not in index")
KeyError: "['Log_Billing'] not in index"
